2025-06-16 10:46:40 - ❌ Błąd w zakładce Transport
Traceback (most recent call last):
  File "spedycja_gui.py", line 52, in __init__
    self.transport_tab = TransportTab(self.notebook, self.lp_counter, self.zlecenia_lista)
                         ~~~~~~~~~~~~^^^^^^^^^^^^^^^^^^^^^^^^^^^^^^^^^^^^^^^^^^^^^^^^^^^^^
  File "transport_tab.py", line 62, in __init__
    filter_frame = ttk.Frame(left)
                             ^^^^
UnboundLocalError: cannot access local variable 'left' where it is not associated with a value

2025-06-16 10:46:40 - ❌ Błąd w zakładce Zlecenia
Traceback (most recent call last):
  File "spedycja_gui.py", line 59, in __init__
    self.zlecenia_tab = ZleceniaTab(self.notebook, transport_tab=self.transport_tab)
                                                                 ^^^^^^^^^^^^^^^^^^
  File "tkinter\__init__.py", line 2546, in __getattr__
AttributeError: '_tkinter.tkapp' object has no attribute 'transport_tab'

2025-06-16 10:47:44 - ❌ Błąd w zakładce Transport
Traceback (most recent call last):
  File "spedycja_gui.py", line 52, in __init__
    self.transport_tab = TransportTab(self.notebook, self.lp_counter, self.zlecenia_lista)
                         ~~~~~~~~~~~~^^^^^^^^^^^^^^^^^^^^^^^^^^^^^^^^^^^^^^^^^^^^^^^^^^^^^
  File "transport_tab.py", line 62, in __init__
    filter_frame = ttk.Frame(left)
                             ^^^^
UnboundLocalError: cannot access local variable 'left' where it is not associated with a value

2025-06-16 10:47:44 - ❌ Błąd w zakładce Zlecenia
Traceback (most recent call last):
  File "spedycja_gui.py", line 59, in __init__
    self.zlecenia_tab = ZleceniaTab(self.notebook, transport_tab=self.transport_tab)
                                                                 ^^^^^^^^^^^^^^^^^^
  File "tkinter\__init__.py", line 2546, in __getattr__
AttributeError: '_tkinter.tkapp' object has no attribute 'transport_tab'

2025-06-16 10:48:33 - ❌ Błąd w zakładce Transport
Traceback (most recent call last):
  File "C:\Users\admin\Desktop\Program Spedycyjny\spedycja\spedycja_gui.py", line 52, in __init__
    self.transport_tab = TransportTab(self.notebook, self.lp_counter, self.zlecenia_lista)
                         ~~~~~~~~~~~~^^^^^^^^^^^^^^^^^^^^^^^^^^^^^^^^^^^^^^^^^^^^^^^^^^^^^
  File "C:\Users\admin\Desktop\Program Spedycyjny\spedycja\transport_tab.py", line 62, in __init__
    filter_frame = ttk.Frame(left)
                             ^^^^
UnboundLocalError: cannot access local variable 'left' where it is not associated with a value

2025-06-16 10:48:33 - ❌ Błąd w zakładce Zlecenia
Traceback (most recent call last):
  File "C:\Users\admin\Desktop\Program Spedycyjny\spedycja\spedycja_gui.py", line 59, in __init__
    self.zlecenia_tab = ZleceniaTab(self.notebook, transport_tab=self.transport_tab)
                                                                 ^^^^^^^^^^^^^^^^^^
  File "C:\Users\admin\AppData\Local\Programs\Python\Python313\Lib\tkinter\__init__.py", line 2546, in __getattr__
    return getattr(self.tk, attr)
AttributeError: '_tkinter.tkapp' object has no attribute 'transport_tab'

2025-06-16 11:04:00 - ❌ Błąd w zakładce Transport
Traceback (most recent call last):
  File "C:\Users\admin\Desktop\Program Spedycyjny\spedycja\spedycja_gui.py", line 52, in __init__
    self.transport_tab = TransportTab(self.notebook, self.lp_counter, self.zlecenia_lista)
                         ~~~~~~~~~~~~^^^^^^^^^^^^^^^^^^^^^^^^^^^^^^^^^^^^^^^^^^^^^^^^^^^^^
  File "C:\Users\admin\Desktop\Program Spedycyjny\spedycja\transport_tab.py", line 62, in __init__
    filter_frame = ttk.Frame(left)
                             ^^^^
UnboundLocalError: cannot access local variable 'left' where it is not associated with a value

2025-06-16 11:04:00 - ❌ Błąd w zakładce Zlecenia
Traceback (most recent call last):
  File "C:\Users\admin\Desktop\Program Spedycyjny\spedycja\spedycja_gui.py", line 59, in __init__
    self.zlecenia_tab = ZleceniaTab(self.notebook, transport_tab=self.transport_tab)
                                                                 ^^^^^^^^^^^^^^^^^^
  File "C:\Users\admin\AppData\Local\Programs\Python\Python313\Lib\tkinter\__init__.py", line 2546, in __getattr__
    return getattr(self.tk, attr)
AttributeError: '_tkinter.tkapp' object has no attribute 'transport_tab'

2025-06-17 08:40:11 - ❌ Błąd w zakładce Ciężarówki
Traceback (most recent call last):
  File "C:\Users\admin\Desktop\Program Spedycyjny\spedycja\spedycja_gui.py", line 80, in __init__
    self.ciezarowki_tab = CiezarowkiTab(self.notebook, self.lp_counter)
                          ~~~~~~~~~~~~~^^^^^^^^^^^^^^^^^^^^^^^^^^^^^^^^
  File "C:\Users\admin\Desktop\Program Spedycyjny\spedycja\ciezarowki_tab.py", line 22, in __init__
    self.create_widgets()
    ~~~~~~~~~~~~~~~~~~~^^
  File "C:\Users\admin\Desktop\Program Spedycyjny\spedycja\ciezarowki_tab.py", line 27, in create_widgets
    form_wrapper = ttk.Frame(content)
                             ^^^^^^^
UnboundLocalError: cannot access local variable 'content' where it is not associated with a value

2025-06-17 08:51:35 - ❌ Błąd w zakładce Kierowcy
Traceback (most recent call last):
  File "C:\Users\admin\Desktop\Program Spedycyjny\spedycja\spedycja_gui.py", line 73, in __init__
    self.kierowcy_tab = KierowcyTab(self.notebook, self.lp_counter)
                        ~~~~~~~~~~~^^^^^^^^^^^^^^^^^^^^^^^^^^^^^^^^
  File "C:\Users\admin\Desktop\Program Spedycyjny\spedycja\kierowcy_tab.py", line 19, in __init__
    self.load_from_server()
    ^^^^^^^^^^^^^^^^^^^^^
AttributeError: 'KierowcyTab' object has no attribute 'load_from_server'

2025-06-17 09:19:05 - ❌ Błąd w zakładce Zlecenia
Traceback (most recent call last):
  File "C:\Users\admin\Desktop\Program Spedycyjny\spedycja\spedycja_gui.py", line 59, in __init__
    self.zlecenia_tab = ZleceniaTab(self.notebook, transport_tab=self.transport_tab)
                        ~~~~~~~~~~~^^^^^^^^^^^^^^^^^^^^^^^^^^^^^^^^^^^^^^^^^^^^^^^^^
  File "C:\Users\admin\Desktop\Program Spedycyjny\spedycja\zlecenia_tab.py", line 21, in __init__
    self.tworz_tabele()
    ^^^^^^^^^^^^^^^^^
AttributeError: 'ZleceniaTab' object has no attribute 'tworz_tabele'

2025-06-17 10:11:45 - ❌ Błąd w zakładce Zlecenia
Traceback (most recent call last):
  File "C:\Users\admin\Desktop\Program Spedycyjny\spedycja\spedycja_gui.py", line 59, in __init__
    self.zlecenia_tab = ZleceniaTab(self.notebook, transport_tab=self.transport_tab)
                        ~~~~~~~~~~~^^^^^^^^^^^^^^^^^^^^^^^^^^^^^^^^^^^^^^^^^^^^^^^^^
  File "C:\Users\admin\Desktop\Program Spedycyjny\spedycja\zlecenia_tab.py", line 20, in __init__
    self.tworz_formularz()
    ~~~~~~~~~~~~~~~~~~~~^^
  File "C:\Users\admin\Desktop\Program Spedycyjny\spedycja\zlecenia_tab.py", line 51, in tworz_formularz
    tk.Button(self.frame_buttons, text="Zapisz zmiany", width=15, command=self.zapisz_zlecenie).grid(row=0, column=2, padx=5)
                                                                          ^^^^^^^^^^^^^^^^^^^^
AttributeError: 'ZleceniaTab' object has no attribute 'zapisz_zlecenie'

2025-06-17 10:14:36 - ❌ Błąd w zakładce Zlecenia
Traceback (most recent call last):
  File "C:\Users\admin\Desktop\Program Spedycyjny\spedycja\spedycja_gui.py", line 59, in __init__
    self.zlecenia_tab = ZleceniaTab(self.notebook, transport_tab=self.transport_tab)
                        ~~~~~~~~~~~^^^^^^^^^^^^^^^^^^^^^^^^^^^^^^^^^^^^^^^^^^^^^^^^^
  File "C:\Users\admin\Desktop\Program Spedycyjny\spedycja\zlecenia_tab.py", line 20, in __init__
    self.tworz_formularz()
    ~~~~~~~~~~~~~~~~~~~~^^
  File "C:\Users\admin\Desktop\Program Spedycyjny\spedycja\zlecenia_tab.py", line 51, in tworz_formularz
    tk.Button(self.frame_buttons, text="Zapisz zmiany", width=15, command=self.zapisz_zlecenie).grid(row=0, column=2, padx=5)
                                                                          ^^^^^^^^^^^^^^^^^^^^
AttributeError: 'ZleceniaTab' object has no attribute 'zapisz_zlecenie'

2025-06-17 10:15:11 - ❌ Błąd w zakładce Zlecenia
Traceback (most recent call last):
  File "C:\Users\admin\Desktop\Program Spedycyjny\spedycja\spedycja_gui.py", line 59, in __init__
    self.zlecenia_tab = ZleceniaTab(self.notebook, transport_tab=self.transport_tab)
                        ~~~~~~~~~~~^^^^^^^^^^^^^^^^^^^^^^^^^^^^^^^^^^^^^^^^^^^^^^^^^
  File "C:\Users\admin\Desktop\Program Spedycyjny\spedycja\zlecenia_tab.py", line 20, in __init__
    self.tworz_formularz()
    ~~~~~~~~~~~~~~~~~~~~^^
  File "C:\Users\admin\Desktop\Program Spedycyjny\spedycja\zlecenia_tab.py", line 51, in tworz_formularz
    tk.Button(self.frame_buttons, text="Zapisz zmiany", width=15, command=self.zapisz_zlecenie).grid(row=0, column=2, padx=5)
                                                                          ^^^^^^^^^^^^^^^^^^^^
AttributeError: 'ZleceniaTab' object has no attribute 'zapisz_zlecenie'

2025-06-17 10:31:19 - ❌ Błąd w zakładce Zlecenia
Traceback (most recent call last):
  File "spedycja_gui.py", line 59, in __init__
    self.zlecenia_tab = ZleceniaTab(self.notebook, transport_tab=self.transport_tab)
                        ~~~~~~~~~~~^^^^^^^^^^^^^^^^^^^^^^^^^^^^^^^^^^^^^^^^^^^^^^^^^
  File "zlecenia_tab.py", line 20, in __init__
    self.tworz_formularz()
    ~~~~~~~~~~~~~~~~~~~~^^
  File "zlecenia_tab.py", line 51, in tworz_formularz
    tk.Button(self.frame_buttons, text="Zapisz zmiany", width=15, command=self.zapisz_zlecenie).grid(row=0, column=2, padx=5)
                                                                          ^^^^^^^^^^^^^^^^^^^^
AttributeError: 'ZleceniaTab' object has no attribute 'zapisz_zlecenie'

2025-06-17 16:31:37 - ❌ Błąd w zakładce Transport
Traceback (most recent call last):
  File "C:\Users\admin\Desktop\Program Spedycyjny\spedycja\spedycja_gui.py", line 52, in __init__
    self.transport_tab = TransportTab(self.notebook, self.lp_counter, self.zlecenia_lista)
                         ~~~~~~~~~~~~^^^^^^^^^^^^^^^^^^^^^^^^^^^^^^^^^^^^^^^^^^^^^^^^^^^^^
  File "C:\Users\admin\Desktop\Program Spedycyjny\spedycja\transport_tab.py", line 10, in __init__
    super().__init__(master, *args, **kwargs)
    ~~~~~~~~~~~~~~~~^^^^^^^^^^^^^^^^^^^^^^^^^
TypeError: Frame.__init__() takes from 1 to 2 positional arguments but 3 were given

2025-06-17 16:31:37 - ❌ Błąd w zakładce Zlecenia
Traceback (most recent call last):
  File "C:\Users\admin\Desktop\Program Spedycyjny\spedycja\spedycja_gui.py", line 59, in __init__
    self.zlecenia_tab = ZleceniaTab(self.notebook, transport_tab=self.transport_tab)
                                                                 ^^^^^^^^^^^^^^^^^^
  File "C:\Users\admin\AppData\Local\Programs\Python\Python313\Lib\tkinter\__init__.py", line 2546, in __getattr__
    return getattr(self.tk, attr)
AttributeError: '_tkinter.tkapp' object has no attribute 'transport_tab'

2025-06-18 10:28:28 - ❌ Błąd w zakładce Transport
Traceback (most recent call last):
  File "C:\Users\admin\Desktop\Program Spedycyjny\spedycja\spedycja_gui.py", line 52, in __init__
    self.transport_tab = TransportTab(self.notebook, self.zlecenia_lista)
                         ~~~~~~~~~~~~^^^^^^^^^^^^^^^^^^^^^^^^^^^^^^^^^^^^
  File "C:\Users\admin\Desktop\Program Spedycyjny\spedycja\transport_tab.py", line 77, in __init__
    tables_frame.grid(row=0, column=0, sticky="nsew", padx=80, pady=10)
    ~~~~~~~~~~~~~~~~~^^^^^^^^^^^^^^^^^^^^^^^^^^^^^^^^^^^^^^^^^^^^^^^^^^
  File "C:\Users\admin\AppData\Local\Programs\Python\Python313\Lib\tkinter\__init__.py", line 2693, in grid_configure
    self.tk.call(
    ~~~~~~~~~~~~^
          ('grid', 'configure', self._w)
          ^^^^^^^^^^^^^^^^^^^^^^^^^^^^^^
          + self._options(cnf, kw))
          ^^^^^^^^^^^^^^^^^^^^^^^^^
_tkinter.TclError: cannot use geometry manager grid inside .!notebook.!transporttab.!frame2 which already has slaves managed by pack

2025-06-18 10:28:28 - ❌ Błąd w zakładce Zlecenia
Traceback (most recent call last):
  File "C:\Users\admin\Desktop\Program Spedycyjny\spedycja\spedycja_gui.py", line 59, in __init__
    self.zlecenia_tab = ZleceniaTab(self.notebook, transport_tab=self.transport_tab)
                                                                 ^^^^^^^^^^^^^^^^^^
  File "C:\Users\admin\AppData\Local\Programs\Python\Python313\Lib\tkinter\__init__.py", line 2546, in __getattr__
    return getattr(self.tk, attr)
AttributeError: '_tkinter.tkapp' object has no attribute 'transport_tab'

2025-06-18 10:31:56 - ❌ Błąd w zakładce Transport
Traceback (most recent call last):
  File "C:\Users\admin\Desktop\Program Spedycyjny\spedycja\spedycja_gui.py", line 52, in __init__
    self.transport_tab = TransportTab(self.notebook, self.zlecenia_lista)
                         ~~~~~~~~~~~~^^^^^^^^^^^^^^^^^^^^^^^^^^^^^^^^^^^^
  File "C:\Users\admin\Desktop\Program Spedycyjny\spedycja\transport_tab.py", line 66, in __init__
    main.grid(row=0, column=0, sticky="nsew", padx=10, pady=10)
    ~~~~~~~~~^^^^^^^^^^^^^^^^^^^^^^^^^^^^^^^^^^^^^^^^^^^^^^^^^^
  File "C:\Users\admin\AppData\Local\Programs\Python\Python313\Lib\tkinter\__init__.py", line 2693, in grid_configure
    self.tk.call(
    ~~~~~~~~~~~~^
          ('grid', 'configure', self._w)
          ^^^^^^^^^^^^^^^^^^^^^^^^^^^^^^
          + self._options(cnf, kw))
          ^^^^^^^^^^^^^^^^^^^^^^^^^
_tkinter.TclError: cannot use geometry manager grid inside .!notebook.!transporttab which already has slaves managed by pack

2025-06-18 10:31:56 - ❌ Błąd w zakładce Zlecenia
Traceback (most recent call last):
  File "C:\Users\admin\Desktop\Program Spedycyjny\spedycja\spedycja_gui.py", line 63, in __init__
    raise Exception("Zakładka Transport nie została załadowana – brak self.transport_tab")
Exception: Zakładka Transport nie została załadowana – brak self.transport_tab

